<?xml version="1.0"?>
<!-- PMC 6-axis Articulated Manipulator -->
<robot name="pmc6r" xmlns:xacro="http://www.ros.org/wiki/xacro">

    <!-- Constants for robot dimensions -->
    <xacro:property name="PI" value="3.1415926535897931"/>
    <xacro:property name="deg" value="0.017453293"/> <!-- Degrees to Radians -->
    <!-- assumption value derive from udacity kuka kr210  12:1 -->
    <xacro:property name="mass0" value="12.5"/> <!-- assumption value for mass -->
    <xacro:property name="mass1" value="11.5"/> <!-- assumption value for mass -->
    <xacro:property name="mass2" value="8.0"/> <!-- assumption value for mass -->
    <xacro:property name="mass3" value="5.9"/> <!-- assumption value for mass -->
    <xacro:property name="mass4" value="1.5"/> <!-- assumption value for mass -->
    <xacro:property name="mass5" value="0.6"/> <!-- assumption value for mass -->
    <xacro:property name="mass6" value="0.04"/> <!-- assumption value for mass -->

    <!-- Import all Gazebo-customization elements, including Gazebo colors -->
    <xacro:include filename="$(find pmc6r_support)/urdf/pmc6r.gazebo" />

    <!-- Add a world link to fix rbot to Gazebo 'base_link' -->
    <link name="world"/>

    <joint name="fixed_base_joint" type="fixed">
        <parent link="world"/>
        <child link="base_link"/>
        <origin xyz="0 0 0" rpy="0 0 0"/>
    </joint>

    <!-- Start the description of robot -->
    <link name="base_link">
        <visual>
            <geometry>
                <mesh filename="package://pmc6r_support/meshes/visual/PMC_BASE.STL"/>
            </geometry>
            <material name="grey">
                <color rgba="0.7 0.7 0.7 1.0"/>
            </material>
        </visual>
        <collision>
            <geometry>
                <mesh filename="package://pmc6r_support/meshes/collision/PMC_BASEc.STL"/>
            </geometry>
        </collision>
        <inertial>
            <origin xyz="0 0 0.2" rpy="0 0 0"/>
            <mass value="${mass0}"/>
            <inertia
                ixx="0.6" ixy="0.0" ixz="0.0"
                iyy="0.7" iyz="0.0"
                izz="1.0"/>
        </inertial>
    </link>


    <link name="link_1">
        <visual>
            <geometry>
                <mesh filename="package://pmc6r_support/meshes/visual/PMC_J1.STL"/>
            </geometry>
            <material name="grey">
                <color rgba="0.7 0.7 0.7 1.0"/>
            </material>
        </visual>
        <collision>
            <geometry>
                <mesh filename="package://pmc6r_support/meshes/collision/PMC_J1c.STL"/>
            </geometry>
        </collision>
        <inertial>
            <origin xyz="0.05 0 0.4" rpy="0 0 0"/>
            <mass value="${mass1}"/>
            <inertia
                ixx="0.3" ixy="0.0" ixz="0.0"
                iyy="0.5" iyz="0.0"
                izz="0.5"/>
        </inertial>
    </link>


    <link name="link_2">
        <visual>
            <geometry>
                <mesh filename="package://pmc6r_support/meshes/visual/PMC_J2.STL"/>
            </geometry>
            <material name="grey">
                <color rgba="0.7 0.7 0.7 1.0"/>
            </material>
        </visual>
        <collision>
            <geometry>
                <mesh filename="package://pmc6r_support/meshes/collision/PMC_J2c.STL"/>
            </geometry>
        </collision>
        <inertial>
            <origin xyz="0 0 0.14" rpy="0 0 0"/>
            <mass value="${mass2}"/>
            <inertia
                ixx="0.4" ixy="0.0" ixz="0.0"
                iyy="0.4" iyz="0.0"
                izz="0.1"/>
        </inertial>
    </link>


    <link name="link_3">
        <visual>
            <geometry>
                <mesh filename="package://pmc6r_support/meshes/visual/PMC_J3.STL"/>
            </geometry>
            <material name="grey">
                <color rgba="0.7 0.7 0.7 1.0"/>
            </material>
        </visual>
        <collision>
            <geometry>
                <mesh filename="package://pmc6r_support/meshes/collision/PMC_J3c.STL"/>
            </geometry>
        </collision>
        <inertial>
            <origin xyz="0.07 0 0.03" rpy="0 0 0"/>
            <mass value="${mass3}"/>
            <inertia
                ixx="0.1" ixy="0.0" ixz="0.0"
                iyy="0.1" iyz="0.0"
                izz="1.0"/>
        </inertial>
    </link>
    <link name="link_4">
        <visual>
            <geometry>
                <mesh filename="package://pmc6r_support/meshes/visual/PMC_J4.STL"/>
            </geometry>
            <material name="grey">
                <color rgba="0.7 0.7 0.7 1.0"/>
            </material>
        </visual>
        <collision>
            <geometry>
                <mesh filename="package://pmc6r_support/meshes/collision/PMC_J4c.STL"/>
            </geometry>
        </collision>
        <inertial>
            <origin xyz="0.14 0 0.03" rpy="0 0 0"/>
            <mass value="${mass4}"/>
            <inertia
                ixx="0.0018" ixy="0.0" ixz="0.0"
                iyy="0.0055" iyz="0.0"
                izz="0.0064"/>
        </inertial>
    </link>

    <link name="link_5">
        <visual>
            <geometry>
                <mesh filename="package://pmc6r_support/meshes/visual/PMC_J5.STL"/>
            </geometry>
            <material name="grey">
                <color rgba="0.7 0.7 0.7 1.0"/>
            </material>
        </visual>
        <collision>
            <geometry>
                <mesh filename="package://pmc6r_support/meshes/collision/PMC_J5c.STL"/>
            </geometry>
        </collision>
        <inertial>
            <origin xyz="0 0 0" rpy="0 0 0"/>
            <mass value="${mass4}"/>
            <inertia
                ixx="0.0004" ixy="0.0" ixz="0.0"
                iyy="0.00068" iyz="0.0"
                izz="0.00068"/>
        </inertial>
    </link>

    <link name="link_6">
        <visual>
            <geometry>
                <mesh filename="package://pmc6r_support/meshes/visual/PMC_J6.STL"/>
            </geometry>
            <material name="grey">
                <color rgba="0.7 0.7 0.7 1.0"/>
            </material>
        </visual>
        <collision>
            <geometry>
                <mesh filename="package://pmc6r_support/meshes/collision/PMC_J6c.STL"/>
            </geometry>
        </collision>
        <inertial>
            <origin xyz="0 0 0" rpy="0 0 0"/>
            <mass value="${mass4}"/>
            <inertia
                ixx="0.00004" ixy="0.0" ixz="0.0"
                iyy="0.00003" iyz="0.0"
                izz="0.00003"/>
        </inertial>
    </link>

    <joint name="joint_1" type="revolute">
        <parent link="base_link"/>
        <child link="link_1"/>
        <origin xyz="0.0 0.0 0.423" rpy="0 0 0"/>
        <axis xyz="0 0 1"/>
        <limit lower="-2.967" upper="2.967" effort="0" velocity="0.5"/>
        <dynamics damping="0.7"/>
    </joint>

    <joint name="joint_2" type="revolute">
        <parent link="link_1"/>
        <child link="link_2"/>
        <origin xyz="0.105 0 0" rpy="0 1.5708 0"/>
        <axis xyz="0 -1 0"/>
        <limit lower="-0.7854" upper="3.3161" effort="0" velocity="0.5"/>
        <dynamics damping="0.7"/>
    </joint>

    <joint name="joint_3" type="revolute">
        <parent link="link_2"/>
        <child link="link_3"/>
        <origin xyz="0 0 0.280" rpy="0 0 0"/>
        <axis xyz="0 -1 0"/>
        <limit lower="-2.0769" upper="2.9496" effort="0" velocity="0.5"/>
        <dynamics damping="0.7"/>
    </joint>

    <joint name="joint_4" type="revolute">
        <parent link="link_3"/>
        <child link="link_4"/>
        <origin xyz="0.284 0 0.065" rpy="0 0 0"/>
        <axis xyz="1 0 0"/>
        <limit lower="-3.3161" upper="3.3161" effort="0" velocity="0.5"/>
        <dynamics damping="0.7"/>
    </joint>

    <joint name="joint_5" type="revolute">
        <parent link="link_4"/>
        <child link="link_5"/>
        <origin xyz="0 0 0" rpy="0 0 0"/>
        <axis xyz="0 -1 0"/>
        <limit lower="-2.0944" upper="2.0944" effort="0" velocity="0.5"/>
        <dynamics damping="0.7"/>
    </joint>

    <joint name="joint_6" type="revolute">
        <parent link="link_5"/>
        <child link="link_6"/>
        <origin xyz="0.0905 0 0" rpy="0 0 0"/>
        <axis xyz="1 0 0"/>
        <limit lower="-6.1086" upper="6.1086" effort="0" velocity="0.5"/>
        <dynamics damping="0.7"/>
    </joint>

    <!--  TODO: Update real gear ratio -->
    <transmission name="tran1">
        <type>transmission_interface/SimpleTransmission</type>
        <joint name="joint_1">
            <hardwareInterface>hardware_interface/PositionJointInterface</hardwareInterface>
        </joint>
        <actuator name="motor_1">
            <hardwareInterface>hardware_interface/PositionJointInterface</hardwareInterface>
            <mechanicalReduction>1</mechanicalReduction>
        </actuator>
    </transmission>

    <transmission name="tran2">
        <type>transmission_interface/SimpleTransmission</type>
        <joint name="joint_2">
            <hardwareInterface>hardware_interface/PositionJointInterface</hardwareInterface>
        </joint>
        <actuator name="motor_2">
            <hardwareInterface>hardware_interface/PositionJointInterface</hardwareInterface>
            <mechanicalReduction>1</mechanicalReduction>
        </actuator>
    </transmission>

    <transmission name="tran3">
        <type>transmission_interface/SimpleTransmission</type>
        <joint name="joint_3">
            <hardwareInterface>hardware_interface/PositionJointInterface</hardwareInterface>
        </joint>
        <actuator name="motor_3">
            <hardwareInterface>hardware_interface/PositionJointInterface</hardwareInterface>
            <mechanicalReduction>1</mechanicalReduction>
        </actuator>
    </transmission>

    <transmission name="tran4">
        <type>transmission_interface/SimpleTransmission</type>
        <joint name="joint_4">
            <hardwareInterface>hardware_interface/PositionJointInterface</hardwareInterface>
        </joint>
        <actuator name="motor_4">
            <hardwareInterface>hardware_interface/PositionJointInterface</hardwareInterface>
            <mechanicalReduction>1</mechanicalReduction>
        </actuator>
    </transmission>

    <transmission name="tran5">
        <type>transmission_interface/SimpleTransmission</type>
        <joint name="joint_5">
            <hardwareInterface>hardware_interface/PositionJointInterface</hardwareInterface>
        </joint>
        <actuator name="motor_5">
            <hardwareInterface>hardware_interface/PositionJointInterface</hardwareInterface>
            <mechanicalReduction>1</mechanicalReduction>
        </actuator>
    </transmission>

    <transmission name="tran6">
        <type>transmission_interface/SimpleTransmission</type>
        <joint name="joint_6">
            <hardwareInterface>hardware_interface/PositionJointInterface</hardwareInterface>
        </joint>
        <actuator name="motor_6">
            <hardwareInterface>hardware_interface/PositionJointInterface</hardwareInterface>
            <mechanicalReduction>1</mechanicalReduction>
        </actuator>
    </transmission>

</robot>
